<mujoco model="tars">
  <compiler angle="radian" />
  <option timestep="0.001" integrator="implicitfast" iterations="50" />
  <default>
    <geom contype="0" conaffinity="0" />
  </default>
  <visual>
    <rgba haze="0.58 0.58 0.58 1" />
    <headlight ambient="0.35 0.35 0.35" diffuse="0.7 0.7 0.7" specular="0.15 0.15 0.15" />
  </visual>
  <asset>
    <texture name="neutral_sky" type="skybox" builtin="flat" rgb1="0.55 0.55 0.55" rgb2="0.55 0.55 0.55" width="64" height="64" />
    <mesh name="side_plate" file="side_plate.stl" />
    <mesh name="faceplate_corner" file="faceplate_corner.stl" />
    <mesh name="corner" file="corner.stl" />
    <mesh name="bearing" file="bearing.stl" />
    <mesh name="connector_tab" file="connector_tab.stl" />
    <mesh name="aluminum_rail" file="aluminum_rail.stl" />
    <mesh name="stepper_mount_active" file="stepper_mount_active.stl" />
    <mesh name="stepper_coupler" file="stepper_coupler.stl" />
    <mesh name="servo_horn" file="servo_horn.stl" />
    <mesh name="funky_tab" file="funky_tab.stl" />
    <mesh name="stepper_mount_fixed" file="stepper_mount_fixed.stl" />
    <mesh name="active_carriage" file="active_carriage_demo.stl" />
    <mesh name="bearing__2" file="bearing__2.stl" />
    <mesh name="philips_m3x30" file="philips_m3x30.stl" />
    <mesh name="jst_s6b_ph_k_s" file="jst_s6b_ph_k_s.stl" />
    <mesh name="bottom_plate" file="bottom_plate.stl" />
    <mesh name="top_plate" file="top_plate.stl" />
    <mesh name="middle_part" file="middle_part.stl" />
    <mesh name="stepper_shaft" file="stepper_shaft.stl" />
    <mesh name="servo" file="servo_demo.stl" />
    <mesh name="fixed_carriage" file="fixed_carriage_demo.stl" />
    <mesh name="internals_visual" file="internals_center_demo.stl" />
    <mesh name="internals_outside_visual" file="internals_outside_demo.stl" />
  </asset>
  <worldbody>
    <geom name="floor" type="plane" size="5 5 0.1" pos="0 0 0" rgba="0.35 0.35 0.35 1" contype="1" conaffinity="1" />
    <light name="key_light" directional="true" dir="0.25 -0.35 -1" diffuse="0.95 0.95 0.95" specular="0.2 0.2 0.2" ambient="0.18 0.18 0.18" />
    <camera name="full_body" pos="-0.05 -2.5 0.5" xyaxes="1 0 0 0 0.2 1" fovy="35" />
    <body name="outer_torso_visual" mocap="true" pos="0.0176706 0.20362195 0.37000284" quat="0.70710678 0.70710678 0 0">
      <geom type="mesh" rgba="0 0 0 0" contype="0" conaffinity="0" mesh="internals_outside_visual" />
    </body>
    <body name="internals" pos="0 0 0.1">
      <inertial pos="-0.0315084 0.202439 0.521923" quat="0.991459 0.00318635 -0.130289 0.00491224" mass="12.5568" diaginertia="0.65197 0.544104 0.237368" />
      <joint type="free" />
      <geom pos="0.0176706 0.20362195 0.37000284" quat="0.70710678 0.70710678 0 0" type="mesh" rgba="0 0 0 0" mesh="internals_visual" />
      <geom pos="0.0334104 0.296836 0.49394" quat="0.67465 -0.674652 -0.211768 -0.211768" type="mesh" rgba="0 0 0 0" mesh="side_plate" />
      <geom pos="0.27927 0.210959 0.200872" quat="1.2659e-06 0.299485 3.97355e-07 -0.954101" type="mesh" rgba="0 0 0 0" mesh="faceplate_corner" />
      <geom pos="-0.008277 0.249211 0.464909" quat="0.626792 -0.327307 0.327308 -0.626794" type="mesh" rgba="0 0 0 0" mesh="side_plate" />
      <geom pos="-0.212449 0.210959 0.787007" quat="1.2659e-06 0.954101 -3.97355e-07 0.299485" type="mesh" rgba="0 0 0 0" mesh="faceplate_corner" />
      <geom pos="0.0334104 0.198411 0.49394" quat="0.67465 -0.674652 -0.211768 -0.211768" type="mesh" rgba="0 0 0 0" mesh="side_plate" />
      <geom pos="0.272012 0.287462 0.211294" quat="0.299485 -8.68541e-07 0.954101 -8.68541e-07" type="mesh" rgba="0 0 0 0" mesh="corner" />
      <geom pos="0.223017 0.287462 0.161697" quat="0.954101 0 -0.299485 0" type="mesh" rgba="0 0 0 0" mesh="corner" />
      <geom pos="0.0724923 0.249211 0.521156" quat="0.626792 -0.327307 0.327308 -0.626794" type="mesh" rgba="0 0 0 0" mesh="side_plate" />
      <geom pos="0.0334104 0.100793 0.49394" quat="0.67465 0.674652 -0.211768 0.211768" type="mesh" rgba="0 0 0 0" mesh="side_plate" />
      <geom pos="-0.156196 0.186669 0.826182" quat="0.299485 -8.68541e-07 0.954101 -8.68541e-07" type="mesh" rgba="0 0 0 0" mesh="faceplate_corner" />
      <geom pos="-0.008277 0.148418 0.464909" quat="0.626792 0.327307 0.327308 0.626794" type="mesh" rgba="0 0 0 0" mesh="side_plate" />
      <geom pos="0.223017 0.186669 0.161697" quat="0.954101 0 -0.299485 0" type="mesh" rgba="0 0 0 0" mesh="faceplate_corner" />
      <geom pos="0.0334104 0.199218 0.49394" quat="0.67465 0.674652 -0.211768 0.211768" type="mesh" rgba="0 0 0 0" mesh="side_plate" />
      <geom pos="-0.148938 0.110167 0.81576" quat="1.2659e-06 0.299485 3.97355e-07 -0.954101" type="mesh" rgba="0 0 0 0" mesh="corner" />
      <geom pos="-0.212449 0.110167 0.787007" quat="1.2659e-06 0.954101 -3.97355e-07 0.299485" type="mesh" rgba="0 0 0 0" mesh="corner" />
      <geom pos="0.0724923 0.148418 0.521156" quat="0.626792 0.327307 0.327308 0.626794" type="mesh" rgba="0 0 0 0" mesh="side_plate" />
      <geom pos="-0.047625 0.09525 0.381" quat="0.707105 -0.707108 0 0" type="mesh" rgba="0 0 0 0" mesh="side_plate" />
      <geom pos="-0.01335 0.00937372 0" quat="1.32679e-06 0 0 1" type="mesh" rgba="0 0 0 0" mesh="faceplate_corner" />
      <geom pos="-0.098425 0.047625 0.381" quat="0.499998 -0.5 0.500002 -0.5" type="mesh" rgba="0 0 0 0" mesh="side_plate" />
      <geom pos="-0.0819 0.00937372 0.762" quat="1.32679e-06 1 0 0" type="mesh" rgba="0 0 0 0" mesh="faceplate_corner" />
      <geom pos="-0.047625 -0.003175 0.381" quat="0.707105 -0.707108 0 0" type="mesh" rgba="0 0 0 0" mesh="side_plate" />
      <geom pos="-0.01335 0.0858763 0.0127" quat="1.76048e-12 -1.32679e-06 -1 1.32679e-06" type="mesh" rgba="0 0 0 0" mesh="corner" />
      <geom pos="-0.0819 0.0858763 0" quat="1 0 0 0" type="mesh" rgba="0 0 0 0" mesh="corner" />
      <geom pos="0 0.047625 0.381" quat="0.499998 -0.5 0.500002 -0.5" type="mesh" rgba="0 0 0 0" mesh="side_plate" />
      <geom pos="-0.047625 0.397628 0.381" quat="9.38184e-07 9.38187e-07 0.707108 0.707105" type="mesh" rgba="0 0 0 0" mesh="side_plate" />
      <geom pos="-0.0819 0.311752 0.762" quat="1.32679e-06 1 0 0" type="mesh" rgba="0 0 0 0" mesh="faceplate_corner" />
      <geom pos="0.003175 0.350003 0.381" quat="0.499998 0.5 -0.500002 -0.5" type="mesh" rgba="0 0 0 0" mesh="side_plate" />
      <geom pos="-0.01335 0.311752 0" quat="1.32679e-06 0 0 1" type="mesh" rgba="0 0 0 0" mesh="faceplate_corner" />
      <geom pos="-0.047625 0.299203 0.381" quat="9.38184e-07 9.38187e-07 0.707108 0.707105" type="mesh" rgba="0 0 0 0" mesh="side_plate" />
      <geom pos="-0.0819 0.388255 0.7493" quat="1 0 0 0" type="mesh" rgba="0 0 0 0" mesh="corner" />
      <geom pos="-0.01335 0.388255 0.762" quat="1.76048e-12 -1.32679e-06 -1 1.32679e-06" type="mesh" rgba="0 0 0 0" mesh="corner" />
      <geom pos="-0.09525 0.350003 0.381" quat="0.499998 0.5 -0.500002 -0.5" type="mesh" rgba="0 0 0 0" mesh="side_plate" />
      <geom pos="-0.156196 0.287462 0.826182" quat="0.299485 -8.68541e-07 0.954101 -8.68541e-07" type="mesh" rgba="0 0 0 0" mesh="corner" />
      <geom pos="0.0579081 0.287462 0.518738" quat="0.299485 -8.68541e-07 0.954101 -8.68541e-07" type="mesh" rgba="0 0 0 0" mesh="corner" />
      <geom pos="0.215759 0.210959 0.172119" quat="1.2659e-06 0.954101 -3.97355e-07 0.299485" type="mesh" rgba="0 0 0 0" mesh="faceplate_corner" />
      <geom pos="0.00165482 0.210959 0.479563" quat="1.2659e-06 0.954101 -3.97355e-07 0.299485" type="mesh" rgba="0 0 0 0" mesh="faceplate_corner" />
      <geom pos="-0.205192 0.287462 0.776586" quat="0.954101 0 -0.299485 0" type="mesh" rgba="0 0 0 0" mesh="corner" />
      <geom pos="0.00891259 0.287462 0.469141" quat="0.954101 0 -0.299485 0" type="mesh" rgba="0 0 0 0" mesh="corner" />
      <geom pos="-0.148938 0.210959 0.81576" quat="1.2659e-06 0.299485 3.97355e-07 -0.954101" type="mesh" rgba="0 0 0 0" mesh="faceplate_corner" />
      <geom pos="0.0651659 0.210959 0.508316" quat="1.2659e-06 0.299485 3.97355e-07 -0.954101" type="mesh" rgba="0 0 0 0" mesh="faceplate_corner" />
      <geom pos="0.27927 0.110167 0.200872" quat="1.2659e-06 0.299485 3.97355e-07 -0.954101" type="mesh" rgba="0 0 0 0" mesh="corner" />
      <geom pos="0.0651659 0.110167 0.508316" quat="1.2659e-06 0.299485 3.97355e-07 -0.954101" type="mesh" rgba="0 0 0 0" mesh="corner" />
      <geom pos="-0.205192 0.186669 0.776586" quat="0.954101 0 -0.299485 0" type="mesh" rgba="0 0 0 0" mesh="faceplate_corner" />
      <geom pos="0.00891259 0.186669 0.469141" quat="0.954101 0 -0.299485 0" type="mesh" rgba="0 0 0 0" mesh="faceplate_corner" />
      <geom pos="0.215759 0.110167 0.172119" quat="1.2659e-06 0.954101 -3.97355e-07 0.299485" type="mesh" rgba="0 0 0 0" mesh="corner" />
      <geom pos="0.00165482 0.110167 0.479563" quat="1.2659e-06 0.954101 -3.97355e-07 0.299485" type="mesh" rgba="0 0 0 0" mesh="corner" />
      <geom pos="0.272012 0.186669 0.211294" quat="0.299485 -8.68541e-07 0.954101 -8.68541e-07" type="mesh" rgba="0 0 0 0" mesh="faceplate_corner" />
      <geom pos="0.0579081 0.186669 0.518738" quat="0.299485 -8.68541e-07 0.954101 -8.68541e-07" type="mesh" rgba="0 0 0 0" mesh="faceplate_corner" />
      <geom pos="-0.01335 0.0858763 0.762" quat="1.76048e-12 -1.32679e-06 -1 1.32679e-06" type="mesh" rgba="0 0 0 0" mesh="corner" />
      <geom pos="-0.01335 0.0858763 0.38735" quat="1.76048e-12 -1.32679e-06 -1 1.32679e-06" type="mesh" rgba="0 0 0 0" mesh="corner" />
      <geom pos="-0.0819 0.00937372 0.0127" quat="1.32679e-06 1 0 0" type="mesh" rgba="0 0 0 0" mesh="faceplate_corner" />
      <geom pos="-0.0819 0.00937372 0.38735" quat="1.32679e-06 1 0 0" type="mesh" rgba="0 0 0 0" mesh="faceplate_corner" />
      <geom pos="-0.0819 0.0858763 0.7493" quat="1 0 0 0" type="mesh" rgba="0 0 0 0" mesh="corner" />
      <geom pos="-0.0819 0.0858763 0.37465" quat="1 0 0 0" type="mesh" rgba="0 0 0 0" mesh="corner" />
      <geom pos="-0.01335 0.00937372 0.7493" quat="1.32679e-06 0 0 1" type="mesh" rgba="0 0 0 0" mesh="faceplate_corner" />
      <geom pos="-0.01335 0.00937372 0.37465" quat="1.32679e-06 0 0 1" type="mesh" rgba="0 0 0 0" mesh="faceplate_corner" />
      <geom pos="-0.0819 0.388255 0" quat="1 0 0 0" type="mesh" rgba="0 0 0 0" mesh="corner" />
      <geom pos="-0.0819 0.388255 0.37465" quat="1 0 0 0" type="mesh" rgba="0 0 0 0" mesh="corner" />
      <geom pos="-0.01335 0.311752 0.7493" quat="1.32679e-06 0 0 1" type="mesh" rgba="0 0 0 0" mesh="faceplate_corner" />
      <geom pos="-0.01335 0.311752 0.37465" quat="1.32679e-06 0 0 1" type="mesh" rgba="0 0 0 0" mesh="faceplate_corner" />
      <geom pos="-0.01335 0.388255 0.0127" quat="1.76043e-12 1.32679e-06 1 1.32679e-06" type="mesh" rgba="0 0 0 0" mesh="corner" />
      <geom pos="-0.01335 0.388255 0.38735" quat="1.76048e-12 -1.32679e-06 -1 1.32679e-06" type="mesh" rgba="0 0 0 0" mesh="corner" />
      <geom pos="-0.0819 0.311752 0.0127" quat="1.32679e-06 1 0 0" type="mesh" rgba="0 0 0 0" mesh="faceplate_corner" />
      <geom pos="-0.0819 0.311752 0.38735" quat="1.32679e-06 1 0 0" type="mesh" rgba="0 0 0 0" mesh="faceplate_corner" />
      <body name="active_carriage_l0" pos="-0.047625 0.0637134 0.68095">
        <inertial pos="-5e-06 -0.0206834 -0.03737" quat="0.498456 0.501391 0.498633 0.501512" mass="0.0853426" diaginertia="8.29012e-05 4.84988e-05 4.8e-05" />
        <joint name="shoulder_prismatic_l0" pos="0 0 0" axis="0 0 1" type="slide" range="-0.2 0" actuatorfrcrange="-100 100" />
        <geom quat="1.76038e-12 1.32679e-06 1 1.32679e-06" type="mesh" rgba="0.615686 0.811765 0.929412 1" mesh="active_carriage" />
        <geom pos="-0.0198283 0.001 0.03375" quat="0.65328 -0.653283 0.270598 -0.270597" type="mesh" rgba="0.0980392 0.0980392 0.0980392 1" mesh="aluminum_rail" />
        <geom pos="0.0198283 0.001 -0.29625" quat="0.270599 0.2706 -0.653282 -0.65328" type="mesh" rgba="0.0980392 0.0980392 0.0980392 1" mesh="aluminum_rail" />
        <geom pos="0 -0.007 0.04275" quat="0.885128 0 0 -0.465347" type="mesh" rgba="0.819608 0.819608 0.819608 1" mesh="bearing__2" />
        <geom pos="0 -0.007 0.07135" quat="0.421534 0 0 -0.906813" type="mesh" rgba="0.819608 0.819608 0.819608 1" mesh="bearing__2" />
        <geom pos="0 0.009 -0.3043" quat="6.1742e-07 -0.465347 0.885128 -1.17438e-06" type="mesh" rgba="0.819608 0.819608 0.819608 1" mesh="bearing__2" />
        <geom pos="0 0.009 -0.3329" quat="1.20316e-06 -0.906814 0.421532 -5.59286e-07" type="mesh" rgba="0.819608 0.819608 0.819608 1" mesh="bearing__2" />
        <body name="servo_l0" pos="0 -0.0145366 -0.0375">
          <inertial pos="-5e-06 -0.0238368 -0.00029" quat="1 0.00088183 0 0" mass="0.356309" diaginertia="0.0001939 0.0001515 9.47998e-05" />
          <joint name="hip_revolute_l0" pos="0 0 0" axis="0 1 0" range="-1.57 1.57" actuatorfrcrange="-10 10" />
          <geom quat="1.76038e-12 1.32679e-06 1 1.32679e-06" type="mesh" rgba="0.4 0.4 0.4 1" mesh="servo" />
          <body name="fixed_carriage_l0" pos="0 0.0165366 0.025693">
            <inertial pos="-0.0187 0.0375505 -0.155085" quat="0.707106 0.000887566 -0.000889069 0.707106" mass="0.101273" diaginertia="7.68003e-05 4.97e-05 3.69997e-05" />
            <joint name="knee_prismatic_l0" pos="0 0 0" axis="0 0 1" type="slide" range="-0.2 0" actuatorfrcrange="-100 100" />
            <geom pos="-0.00070524 -0.01598397 0.04772368" quat="0.707 -0.707 0 0" type="mesh" mesh="fixed_carriage" />
            <geom size="0.008 0.235161" type="cylinder" rgba="0.1 0.1 0.1 1" contype="1" conaffinity="1" />
            <geom size="0.04 0.04 0.01" type="box" rgba="0 0 0 0" contype="1" conaffinity="1" />
          </body>
        </body>
      </body>
      <body name="active_carriage_l1" pos="-0.047625 0.366092 0.553892">
        <inertial pos="-5e-06 -0.323062 0.089688" quat="0.498456 0.501391 0.498633 0.501512" mass="0.0853426" diaginertia="8.29012e-05 4.84988e-05 4.8e-05" />
        <joint name="shoulder_prismatic_l1" pos="0 0 0" axis="0 0 1" type="slide" range="-0.2 0" actuatorfrcrange="-100 100" />
        <geom type="mesh" rgba="0.615686 0.811765 0.929412 1" mesh="active_carriage" />
        <geom pos="0.0198283 0.001 -0.168042" quat="0.270599 0.2706 -0.653282 -0.65328" type="mesh" rgba="0.0980392 0.0980392 0.0980392 1" mesh="aluminum_rail" />
        <geom pos="-0.0198283 0.001 0.161958" quat="0.65328 -0.653283 0.270598 -0.270597" type="mesh" rgba="0.0980392 0.0980392 0.0980392 1" mesh="aluminum_rail" />
        <geom pos="0 -0.007 -0.177042" quat="6.1742e-07 -0.465347 0.885128 -1.17438e-06" type="mesh" rgba="0.819608 0.819608 0.819608 1" mesh="bearing__2" />
        <geom pos="0 -0.007 -0.205642" quat="1.20316e-06 -0.906814 0.421532 -5.59286e-07" type="mesh" rgba="0.819608 0.819608 0.819608 1" mesh="bearing__2" />
        <geom pos="0 0.009 0.170008" quat="0.885128 0 0 -0.465347" type="mesh" rgba="0.819608 0.819608 0.819608 1" mesh="bearing__2" />
        <geom pos="0 0.009 0.198608" quat="0.421534 0 0 -0.906813" type="mesh" rgba="0.819608 0.819608 0.819608 1" mesh="bearing__2" />
        <body name="servo_l1" pos="0 -0.014537 0.0375">
          <inertial pos="-5e-06 -0.326215 0.051768" quat="1 0.00088183 0 0" mass="0.356309" diaginertia="0.0001939 0.0001515 9.47998e-05" />
          <joint name="hip_revolute_l1" pos="0 0 0" axis="0 1 0" range="-1.57 1.57" actuatorfrcrange="-10 10" />
          <geom type="mesh" rgba="0.4 0.4 0.4 1" mesh="servo" />
          <body name="fixed_carriage_l1" pos="0 0.016537 -0.018156">
            <inertial pos="-0.0153251 -0.264828 -0.0477584" quat="0.707106 0.000887566 -0.000889069 0.707106" mass="0.101273" diaginertia="7.68003e-05 4.97e-05 3.69997e-05" />
            <joint name="knee_prismatic_l1" pos="0 0 0" axis="0 0 1" type="slide" range="-0.2 0" actuatorfrcrange="-100 100" />
            <geom pos="-0.00070524 -0.01598397 0.04772368" quat="0.707 -0.707 0 0" type="mesh" mesh="fixed_carriage" />
            <geom size="0.008 0.234483" type="cylinder" rgba="0.1 0.1 0.1 1" contype="1" conaffinity="1" />
            <geom size="0.04 0.04 0.01" type="box" rgba="0 0 0 0" contype="1" conaffinity="1" />
          </body>
        </body>
      </body>
      <body name="active_carriage_l2" pos="-0.0812508 0.267299 0.658588">
        <inertial pos="0.0336208 -0.224269 -0.015008" quat="0.498456 0.501391 0.498633 0.501512" mass="0.0853426" diaginertia="8.29012e-05 4.84988e-05 4.8e-05" />
        <joint name="shoulder_prismatic_l2" pos="0 0 0" axis="0 0 1" type="slide" range="-0.2 0" actuatorfrcrange="-100 100" />
        <geom quat="1.2659e-06 0.954101 -3.97355e-07 0.299485" type="mesh" rgba="0.615686 0.811765 0.929412 1" mesh="active_carriage" />
        <geom pos="-0.0923122 -0.001 0.09786" quat="0.704338 -0.542255 0.0625292 -0.453826" type="mesh" rgba="0.0980392 0.0980392 0.0980392 1" mesh="aluminum_rail" />
        <geom pos="0.1288181 -0.001 -0.150281" quat="0.0625305 0.453827 -0.704336 -0.542256" type="mesh" rgba="0.0980392 0.0980392 0.0980392 1" mesh="aluminum_rail" />
        <geom pos="0.1171471 0.007 -0.168218" quat="0.265083 -0.44399 0.844501 -0.139363" type="mesh" rgba="0.819608 0.819608 0.819608 1" mesh="bearing__2" />
        <geom pos="0.1334914 0.007 -0.191688" quat="0.126244 -0.865191 0.402184 -0.271578" type="mesh" rgba="0.819608 0.819608 0.819608 1" mesh="bearing__2" />
        <geom pos="-0.0811842 -0.009 0.116577" quat="0.844501 0.139364 -0.265083 -0.443989" type="mesh" rgba="0.819608 0.819608 0.819608 1" mesh="bearing__2" />
        <geom pos="-0.0975282 -0.009 0.140047" quat="0.402184 0.271577 -0.126243 -0.865192" type="mesh" rgba="0.819608 0.819608 0.819608 1" mesh="bearing__2" />
        <body name="servo_l2" pos="0.017020875 -0.016037 -0.015066">
          <inertial pos="0.008193475 -0.25062025 0.025812" quat="1 0.00088183 0 0" mass="0.356309" diaginertia="0.0001939 0.0001515 9.47998e-05" />
          <joint name="hip_revolute_l2" pos="0 0 0" axis="0 1 0" range="-1.57 1.57" actuatorfrcrange="-10 10" />
          <geom quat="0.299485 -8.68541e-07 0.954101 -8.68541e-07" type="mesh" rgba="0.4 0.4 0.4 1" mesh="servo" />
      <body name="fixed_carriage_l2" pos="-0.017020875 0.016537 -0.018156">
            <inertial pos="-0.017121275 -0.18923325 -0.15013835" quat="0.707106 0.000887566 -0.000889069 0.707106" mass="0.101273" diaginertia="7.68003e-05 4.97e-05 3.69997e-05" />
            <joint name="knee_prismatic_l2" pos="0 0 0" axis="0 0 1" type="slide" range="-0.2 0" actuatorfrcrange="-100 100" />
            <geom pos="-0.00070524 -0.01598397 0.04772368" quat="0.707 -0.707 0 0" type="mesh" mesh="fixed_carriage" />
            <geom size="0.008 0.21412" type="cylinder" rgba="0.1 0.1 0.1 1" contype="1" conaffinity="1" />
            <geom size="0.04 0.04 0.01" type="box" rgba="0 0 0 0" contype="1" conaffinity="1" />
          </body>
        </body>
      </body>
      <body name="active_carriage_l3" pos="-0.0798627 0.164506 0.656595">
        <inertial pos="0.0322327 -0.121476 -0.013015" quat="0.498456 0.501391 0.498633 0.501512" mass="0.0853426" diaginertia="8.29012e-05 4.84988e-05 4.8e-05" />
        <joint name="shoulder_prismatic_l3" pos="0 0 0" axis="0 0 1" type="slide" range="-0.2 0" actuatorfrcrange="-100 100" />
        <geom quat="0.299485 -8.68541e-07 0.954101 -8.68541e-07" type="mesh" rgba="0.615686 0.811765 0.929412 1" mesh="active_carriage" />
        <geom pos="-0.0937003 0.001 0.099853" quat="0.704338 -0.542255 0.0625292 -0.453826" type="mesh" rgba="0.0980392 0.0980392 0.0980392 1" mesh="aluminum_rail" />
        <geom pos="0.12743 0.001 -0.148288" quat="0.0625305 0.453827 -0.704336 -0.542256" type="mesh" rgba="0.0980392 0.0980392 0.0980392 1" mesh="aluminum_rail" />
        <geom pos="0.115759 0.009 -0.166225" quat="0.265083 -0.44399 0.844501 -0.139363" type="mesh" rgba="0.819608 0.819608 0.819608 1" mesh="bearing__2" />
        <geom pos="0.1321033 0.009 -0.189695" quat="0.126244 -0.865191 0.402184 -0.271578" type="mesh" rgba="0.819608 0.819608 0.819608 1" mesh="bearing__2" />
        <geom pos="-0.0825723 -0.007 0.11857" quat="0.844501 0.139364 -0.265083 -0.443989" type="mesh" rgba="0.819608 0.819608 0.819608 1" mesh="bearing__2" />
        <geom pos="-0.0989163 -0.007 0.14204" quat="0.402184 0.271577 -0.126243 -0.865192" type="mesh" rgba="0.819608 0.819608 0.819608 1" mesh="bearing__2" />
        <body name="servo_l3" pos="0.0214305 -0.014536 -0.030773">
          <inertial pos="0.0108022 -0.12463 0.017338" quat="1 0.00088183 0 0" mass="0.356309" diaginertia="0.0001939 0.0001515 9.47998e-05" />
          <joint name="hip_revolute_l3" pos="0 0 0" axis="0 1 0" range="-1.57 1.57" actuatorfrcrange="-10 10" />
          <geom quat="0.299485 -8.68541e-07 0.954101 -8.68541e-07" type="mesh" rgba="0.4 0.4 0.4 1" mesh="servo" />
      <body name="fixed_carriage_l3" pos="-0.0214305 0.014536 0.025693">
            <inertial pos="0.0708434 -0.0980501 -0.136688" quat="0.707106 0.000887566 -0.000889069 0.707106" mass="0.101273" diaginertia="7.68003e-05 4.97e-05 3.69997e-05" />
            <joint name="knee_prismatic_l3" pos="0 0 0" axis="0 0 1" type="slide" range="-0.2 0" actuatorfrcrange="-100 100" />
            <geom pos="-0.00070524 -0.01598397 0.04772368" quat="0.707 -0.707 0 0" type="mesh" mesh="fixed_carriage" />
            <geom size="0.008 0.209843" type="cylinder" rgba="0.1 0.1 0.1 1" contype="1" conaffinity="1" />
            <geom size="0.04 0.04 0.01" type="box" rgba="0 0 0 0" contype="1" conaffinity="1" />
          </body>
        </body>
      </body>
    </body>
  </worldbody>
  <actuator>
    <position name="shoulder_l0" joint="shoulder_prismatic_l0" kp="2000" />
    <position name="hip_l0" joint="hip_revolute_l0" kp="200" />
    <position name="knee_l0" joint="knee_prismatic_l0" kp="2000" />
    <position name="shoulder_l1" joint="shoulder_prismatic_l1" kp="2000" />
    <position name="hip_l1" joint="hip_revolute_l1" kp="200" />
    <position name="knee_l1" joint="knee_prismatic_l1" kp="2000" />
    <position name="shoulder_l2" joint="shoulder_prismatic_l2" kp="2000" />
    <position name="hip_l2" joint="hip_revolute_l2" kp="200" />
    <position name="knee_l2" joint="knee_prismatic_l2" kp="2000" />
    <position name="shoulder_l3" joint="shoulder_prismatic_l3" kp="2000" />
    <position name="hip_l3" joint="hip_revolute_l3" kp="200" />
    <position name="knee_l3" joint="knee_prismatic_l3" kp="2000" />
  </actuator>
</mujoco>
